2023-04-30 19:33:34,613 -  nornir.core -     INFO -        run() - Running task 'hello_world' with args {} on 6 hosts
2023-04-30 19:34:27,703 -  nornir.core -     INFO -        run() - Running task 'hello_world' with args {} on 6 hosts
2023-04-30 19:39:30,922 -  nornir.core -     INFO -        run() - Running task 'hello_world' with args {} on 6 hosts
2023-04-30 19:49:13,368 -  nornir.core -     INFO -        run() - Running task 'hello_world' with args {} on 2 hosts
2023-04-30 19:59:47,031 -  nornir.core -     INFO -        run() - Running task 'napalm_cli' with args {'commands': ['show ip int br']} on 4 hosts
2023-04-30 19:59:47,698 - nornir.core.task -    ERROR -      start() - Host 'R1-CPE-BAT-A': task 'napalm_cli' failed with traceback:
Traceback (most recent call last):
  File "/home/cpe/.local/share/virtualenvs/devnet-rPqD-W-P/lib/python3.8/site-packages/netmiko/base_connection.py", line 1046, in establish_connection
    self.remote_conn_pre.connect(**ssh_connect_params)
  File "/home/cpe/.local/share/virtualenvs/devnet-rPqD-W-P/lib/python3.8/site-packages/paramiko/client.py", line 459, in connect
    self._auth(
  File "/home/cpe/.local/share/virtualenvs/devnet-rPqD-W-P/lib/python3.8/site-packages/paramiko/client.py", line 791, in _auth
    raise SSHException("No authentication methods available")
paramiko.ssh_exception.SSHException: No authentication methods available

During handling of the above exception, another exception occurred:

Traceback (most recent call last):
  File "/home/cpe/.local/share/virtualenvs/devnet-rPqD-W-P/lib/python3.8/site-packages/napalm/base/base.py", line 113, in _netmiko_open
    self._netmiko_device = ConnectHandler(
  File "/home/cpe/.local/share/virtualenvs/devnet-rPqD-W-P/lib/python3.8/site-packages/netmiko/ssh_dispatcher.py", line 365, in ConnectHandler
    return ConnectionClass(*args, **kwargs)
  File "/home/cpe/.local/share/virtualenvs/devnet-rPqD-W-P/lib/python3.8/site-packages/netmiko/base_connection.py", line 439, in __init__
    self._open()
  File "/home/cpe/.local/share/virtualenvs/devnet-rPqD-W-P/lib/python3.8/site-packages/netmiko/base_connection.py", line 444, in _open
    self.establish_connection()
  File "/home/cpe/.local/share/virtualenvs/devnet-rPqD-W-P/lib/python3.8/site-packages/netmiko/base_connection.py", line 1099, in establish_connection
    raise NetmikoTimeoutException(msg)
netmiko.exceptions.NetmikoTimeoutException: 
A paramiko SSHException occurred during connection creation:

No authentication methods available



During handling of the above exception, another exception occurred:

Traceback (most recent call last):
  File "/home/cpe/.local/share/virtualenvs/devnet-rPqD-W-P/lib/python3.8/site-packages/nornir/core/task.py", line 99, in start
    r = self.task(self, **self.params)
  File "/home/cpe/.local/share/virtualenvs/devnet-rPqD-W-P/lib/python3.8/site-packages/nornir_napalm/plugins/tasks/napalm_cli.py", line 19, in napalm_cli
    device = task.host.get_connection(CONNECTION_NAME, task.nornir.config)
  File "/home/cpe/.local/share/virtualenvs/devnet-rPqD-W-P/lib/python3.8/site-packages/nornir/core/inventory.py", line 494, in get_connection
    self.open_connection(
  File "/home/cpe/.local/share/virtualenvs/devnet-rPqD-W-P/lib/python3.8/site-packages/nornir/core/inventory.py", line 546, in open_connection
    conn_obj.open(
  File "/home/cpe/.local/share/virtualenvs/devnet-rPqD-W-P/lib/python3.8/site-packages/nornir_napalm/plugins/connections/__init__.py", line 57, in open
    connection.open()
  File "/home/cpe/.local/share/virtualenvs/devnet-rPqD-W-P/lib/python3.8/site-packages/napalm/ios/ios.py", line 170, in open
    self.device = self._netmiko_open(
  File "/home/cpe/.local/share/virtualenvs/devnet-rPqD-W-P/lib/python3.8/site-packages/napalm/base/base.py", line 122, in _netmiko_open
    raise ConnectionException("Cannot connect to {}".format(self.hostname))
napalm.base.exceptions.ConnectionException: Cannot connect to 172.16.100.125

2023-04-30 19:59:48,054 - nornir.core.task -    ERROR -      start() - Host 'R2-CPE-BAT-A': task 'napalm_cli' failed with traceback:
Traceback (most recent call last):
  File "/home/cpe/.local/share/virtualenvs/devnet-rPqD-W-P/lib/python3.8/site-packages/netmiko/base_connection.py", line 1046, in establish_connection
    self.remote_conn_pre.connect(**ssh_connect_params)
  File "/home/cpe/.local/share/virtualenvs/devnet-rPqD-W-P/lib/python3.8/site-packages/paramiko/client.py", line 459, in connect
    self._auth(
  File "/home/cpe/.local/share/virtualenvs/devnet-rPqD-W-P/lib/python3.8/site-packages/paramiko/client.py", line 791, in _auth
    raise SSHException("No authentication methods available")
paramiko.ssh_exception.SSHException: No authentication methods available

During handling of the above exception, another exception occurred:

Traceback (most recent call last):
  File "/home/cpe/.local/share/virtualenvs/devnet-rPqD-W-P/lib/python3.8/site-packages/napalm/base/base.py", line 113, in _netmiko_open
    self._netmiko_device = ConnectHandler(
  File "/home/cpe/.local/share/virtualenvs/devnet-rPqD-W-P/lib/python3.8/site-packages/netmiko/ssh_dispatcher.py", line 365, in ConnectHandler
    return ConnectionClass(*args, **kwargs)
  File "/home/cpe/.local/share/virtualenvs/devnet-rPqD-W-P/lib/python3.8/site-packages/netmiko/base_connection.py", line 439, in __init__
    self._open()
  File "/home/cpe/.local/share/virtualenvs/devnet-rPqD-W-P/lib/python3.8/site-packages/netmiko/base_connection.py", line 444, in _open
    self.establish_connection()
  File "/home/cpe/.local/share/virtualenvs/devnet-rPqD-W-P/lib/python3.8/site-packages/netmiko/base_connection.py", line 1099, in establish_connection
    raise NetmikoTimeoutException(msg)
netmiko.exceptions.NetmikoTimeoutException: 
A paramiko SSHException occurred during connection creation:

No authentication methods available



During handling of the above exception, another exception occurred:

Traceback (most recent call last):
  File "/home/cpe/.local/share/virtualenvs/devnet-rPqD-W-P/lib/python3.8/site-packages/nornir/core/task.py", line 99, in start
    r = self.task(self, **self.params)
  File "/home/cpe/.local/share/virtualenvs/devnet-rPqD-W-P/lib/python3.8/site-packages/nornir_napalm/plugins/tasks/napalm_cli.py", line 19, in napalm_cli
    device = task.host.get_connection(CONNECTION_NAME, task.nornir.config)
  File "/home/cpe/.local/share/virtualenvs/devnet-rPqD-W-P/lib/python3.8/site-packages/nornir/core/inventory.py", line 494, in get_connection
    self.open_connection(
  File "/home/cpe/.local/share/virtualenvs/devnet-rPqD-W-P/lib/python3.8/site-packages/nornir/core/inventory.py", line 546, in open_connection
    conn_obj.open(
  File "/home/cpe/.local/share/virtualenvs/devnet-rPqD-W-P/lib/python3.8/site-packages/nornir_napalm/plugins/connections/__init__.py", line 57, in open
    connection.open()
  File "/home/cpe/.local/share/virtualenvs/devnet-rPqD-W-P/lib/python3.8/site-packages/napalm/ios/ios.py", line 170, in open
    self.device = self._netmiko_open(
  File "/home/cpe/.local/share/virtualenvs/devnet-rPqD-W-P/lib/python3.8/site-packages/napalm/base/base.py", line 122, in _netmiko_open
    raise ConnectionException("Cannot connect to {}".format(self.hostname))
napalm.base.exceptions.ConnectionException: Cannot connect to 172.16.100.126

2023-04-30 19:59:48,057 - nornir.core.task -    ERROR -      start() - Host 'R2-CPE-BAT-B': task 'napalm_cli' failed with traceback:
Traceback (most recent call last):
  File "/home/cpe/.local/share/virtualenvs/devnet-rPqD-W-P/lib/python3.8/site-packages/netmiko/base_connection.py", line 1046, in establish_connection
    self.remote_conn_pre.connect(**ssh_connect_params)
  File "/home/cpe/.local/share/virtualenvs/devnet-rPqD-W-P/lib/python3.8/site-packages/paramiko/client.py", line 459, in connect
    self._auth(
  File "/home/cpe/.local/share/virtualenvs/devnet-rPqD-W-P/lib/python3.8/site-packages/paramiko/client.py", line 791, in _auth
    raise SSHException("No authentication methods available")
paramiko.ssh_exception.SSHException: No authentication methods available

During handling of the above exception, another exception occurred:

Traceback (most recent call last):
  File "/home/cpe/.local/share/virtualenvs/devnet-rPqD-W-P/lib/python3.8/site-packages/napalm/base/base.py", line 113, in _netmiko_open
    self._netmiko_device = ConnectHandler(
  File "/home/cpe/.local/share/virtualenvs/devnet-rPqD-W-P/lib/python3.8/site-packages/netmiko/ssh_dispatcher.py", line 365, in ConnectHandler
    return ConnectionClass(*args, **kwargs)
  File "/home/cpe/.local/share/virtualenvs/devnet-rPqD-W-P/lib/python3.8/site-packages/netmiko/base_connection.py", line 439, in __init__
    self._open()
  File "/home/cpe/.local/share/virtualenvs/devnet-rPqD-W-P/lib/python3.8/site-packages/netmiko/base_connection.py", line 444, in _open
    self.establish_connection()
  File "/home/cpe/.local/share/virtualenvs/devnet-rPqD-W-P/lib/python3.8/site-packages/netmiko/base_connection.py", line 1099, in establish_connection
    raise NetmikoTimeoutException(msg)
netmiko.exceptions.NetmikoTimeoutException: 
A paramiko SSHException occurred during connection creation:

No authentication methods available



During handling of the above exception, another exception occurred:

Traceback (most recent call last):
  File "/home/cpe/.local/share/virtualenvs/devnet-rPqD-W-P/lib/python3.8/site-packages/nornir/core/task.py", line 99, in start
    r = self.task(self, **self.params)
  File "/home/cpe/.local/share/virtualenvs/devnet-rPqD-W-P/lib/python3.8/site-packages/nornir_napalm/plugins/tasks/napalm_cli.py", line 19, in napalm_cli
    device = task.host.get_connection(CONNECTION_NAME, task.nornir.config)
  File "/home/cpe/.local/share/virtualenvs/devnet-rPqD-W-P/lib/python3.8/site-packages/nornir/core/inventory.py", line 494, in get_connection
    self.open_connection(
  File "/home/cpe/.local/share/virtualenvs/devnet-rPqD-W-P/lib/python3.8/site-packages/nornir/core/inventory.py", line 546, in open_connection
    conn_obj.open(
  File "/home/cpe/.local/share/virtualenvs/devnet-rPqD-W-P/lib/python3.8/site-packages/nornir_napalm/plugins/connections/__init__.py", line 57, in open
    connection.open()
  File "/home/cpe/.local/share/virtualenvs/devnet-rPqD-W-P/lib/python3.8/site-packages/napalm/ios/ios.py", line 170, in open
    self.device = self._netmiko_open(
  File "/home/cpe/.local/share/virtualenvs/devnet-rPqD-W-P/lib/python3.8/site-packages/napalm/base/base.py", line 122, in _netmiko_open
    raise ConnectionException("Cannot connect to {}".format(self.hostname))
napalm.base.exceptions.ConnectionException: Cannot connect to 172.16.100.190

2023-04-30 19:59:48,060 - nornir.core.task -    ERROR -      start() - Host 'R1-CPE-BAT-B': task 'napalm_cli' failed with traceback:
Traceback (most recent call last):
  File "/home/cpe/.local/share/virtualenvs/devnet-rPqD-W-P/lib/python3.8/site-packages/netmiko/base_connection.py", line 1046, in establish_connection
    self.remote_conn_pre.connect(**ssh_connect_params)
  File "/home/cpe/.local/share/virtualenvs/devnet-rPqD-W-P/lib/python3.8/site-packages/paramiko/client.py", line 459, in connect
    self._auth(
  File "/home/cpe/.local/share/virtualenvs/devnet-rPqD-W-P/lib/python3.8/site-packages/paramiko/client.py", line 791, in _auth
    raise SSHException("No authentication methods available")
paramiko.ssh_exception.SSHException: No authentication methods available

During handling of the above exception, another exception occurred:

Traceback (most recent call last):
  File "/home/cpe/.local/share/virtualenvs/devnet-rPqD-W-P/lib/python3.8/site-packages/napalm/base/base.py", line 113, in _netmiko_open
    self._netmiko_device = ConnectHandler(
  File "/home/cpe/.local/share/virtualenvs/devnet-rPqD-W-P/lib/python3.8/site-packages/netmiko/ssh_dispatcher.py", line 365, in ConnectHandler
    return ConnectionClass(*args, **kwargs)
  File "/home/cpe/.local/share/virtualenvs/devnet-rPqD-W-P/lib/python3.8/site-packages/netmiko/base_connection.py", line 439, in __init__
    self._open()
  File "/home/cpe/.local/share/virtualenvs/devnet-rPqD-W-P/lib/python3.8/site-packages/netmiko/base_connection.py", line 444, in _open
    self.establish_connection()
  File "/home/cpe/.local/share/virtualenvs/devnet-rPqD-W-P/lib/python3.8/site-packages/netmiko/base_connection.py", line 1099, in establish_connection
    raise NetmikoTimeoutException(msg)
netmiko.exceptions.NetmikoTimeoutException: 
A paramiko SSHException occurred during connection creation:

No authentication methods available



During handling of the above exception, another exception occurred:

Traceback (most recent call last):
  File "/home/cpe/.local/share/virtualenvs/devnet-rPqD-W-P/lib/python3.8/site-packages/nornir/core/task.py", line 99, in start
    r = self.task(self, **self.params)
  File "/home/cpe/.local/share/virtualenvs/devnet-rPqD-W-P/lib/python3.8/site-packages/nornir_napalm/plugins/tasks/napalm_cli.py", line 19, in napalm_cli
    device = task.host.get_connection(CONNECTION_NAME, task.nornir.config)
  File "/home/cpe/.local/share/virtualenvs/devnet-rPqD-W-P/lib/python3.8/site-packages/nornir/core/inventory.py", line 494, in get_connection
    self.open_connection(
  File "/home/cpe/.local/share/virtualenvs/devnet-rPqD-W-P/lib/python3.8/site-packages/nornir/core/inventory.py", line 546, in open_connection
    conn_obj.open(
  File "/home/cpe/.local/share/virtualenvs/devnet-rPqD-W-P/lib/python3.8/site-packages/nornir_napalm/plugins/connections/__init__.py", line 57, in open
    connection.open()
  File "/home/cpe/.local/share/virtualenvs/devnet-rPqD-W-P/lib/python3.8/site-packages/napalm/ios/ios.py", line 170, in open
    self.device = self._netmiko_open(
  File "/home/cpe/.local/share/virtualenvs/devnet-rPqD-W-P/lib/python3.8/site-packages/napalm/base/base.py", line 122, in _netmiko_open
    raise ConnectionException("Cannot connect to {}".format(self.hostname))
napalm.base.exceptions.ConnectionException: Cannot connect to 172.16.100.189

2023-04-30 20:05:44,697 -  nornir.core -     INFO -        run() - Running task 'napalm_cli' with args {'commands': ['show ip int br']} on 4 hosts
2023-04-30 20:06:59,757 -  nornir.core -     INFO -        run() - Running task 'napalm_get' with args {'getters': ['arp_table']} on 2 hosts
2023-04-30 20:15:44,293 -  nornir.core -     INFO -        run() - Running task 'napalm_get' with args {'getters': ['arp_table']} on 2 hosts
2023-04-30 20:19:13,950 -  nornir.core -     INFO -        run() - Running task 'napalm_configure' with args {'configuration': 'interface Loopback 1 \n ip address 1.1.1.1 255.255.255.255'} on 1 hosts
2023-04-30 20:19:21,599 -  nornir.core -     INFO -        run() - Running task 'napalm_configure' with args {'configuration': 'interface Loopback 1 \n ip address 2.2.2.2 255.255.255.255'} on 1 hosts
2023-04-30 20:22:38,151 -  nornir.core -     INFO -        run() - Running task 'save' with args {} on 6 hosts
2023-04-30 20:24:31,600 -  nornir.core -     INFO -        run() - Running task 'state' with args {} on 6 hosts
2023-04-30 20:29:11,853 -  nornir.core -     INFO -        run() - Running task 'netmiko_send_command' with args {'config_command': ['interface Loopback 2', 'ip address 1.1.1.2 255.255.255.255']} on 1 hosts
2023-04-30 20:29:11,854 - nornir.core.task -    ERROR -      start() - Host 'R1-CPE-BAT-A': task 'netmiko_send_command' failed with traceback:
Traceback (most recent call last):
  File "/home/cpe/.local/share/virtualenvs/devnet-rPqD-W-P/lib/python3.8/site-packages/nornir/core/task.py", line 99, in start
    r = self.task(self, **self.params)
TypeError: netmiko_send_command() missing 1 required positional argument: 'command_string'

2023-04-30 20:29:11,860 -  nornir.core -     INFO -        run() - Running task 'netmiko_send_command' with args {'config_command': ['interface Loopback 2', 'ip address 2.2.2.3 255.255.255.255']} on 1 hosts
2023-04-30 20:29:11,861 - nornir.core.task -    ERROR -      start() - Host 'R2-CPE-BAT-A': task 'netmiko_send_command' failed with traceback:
Traceback (most recent call last):
  File "/home/cpe/.local/share/virtualenvs/devnet-rPqD-W-P/lib/python3.8/site-packages/nornir/core/task.py", line 99, in start
    r = self.task(self, **self.params)
TypeError: netmiko_send_command() missing 1 required positional argument: 'command_string'

2023-04-30 20:29:29,571 -  nornir.core -     INFO -        run() - Running task 'netmiko_send_command' with args {'config_commands': ['interface Loopback 2', 'ip address 1.1.1.2 255.255.255.255']} on 1 hosts
2023-04-30 20:29:29,573 - nornir.core.task -    ERROR -      start() - Host 'R1-CPE-BAT-A': task 'netmiko_send_command' failed with traceback:
Traceback (most recent call last):
  File "/home/cpe/.local/share/virtualenvs/devnet-rPqD-W-P/lib/python3.8/site-packages/nornir/core/task.py", line 99, in start
    r = self.task(self, **self.params)
TypeError: netmiko_send_command() missing 1 required positional argument: 'command_string'

2023-04-30 20:29:29,579 -  nornir.core -     INFO -        run() - Running task 'netmiko_send_command' with args {'config_commands': ['interface Loopback 2', 'ip address 2.2.2.3 255.255.255.255']} on 1 hosts
2023-04-30 20:29:29,580 - nornir.core.task -    ERROR -      start() - Host 'R2-CPE-BAT-A': task 'netmiko_send_command' failed with traceback:
Traceback (most recent call last):
  File "/home/cpe/.local/share/virtualenvs/devnet-rPqD-W-P/lib/python3.8/site-packages/nornir/core/task.py", line 99, in start
    r = self.task(self, **self.params)
TypeError: netmiko_send_command() missing 1 required positional argument: 'command_string'

2023-04-30 20:30:59,908 -  nornir.core -     INFO -        run() - Running task 'netmiko_send_config' with args {'config_commands': ['interface Loopback 2', 'ip address 1.1.1.2 255.255.255.255']} on 1 hosts
2023-04-30 20:31:01,198 -  nornir.core -     INFO -        run() - Running task 'netmiko_send_config' with args {'config_commands': ['interface Loopback 2', 'ip address 2.2.2.3 255.255.255.255']} on 1 hosts
2023-04-30 20:32:04,424 -  nornir.core -     INFO -        run() - Running task 'netmiko_save_config' with args {} on 1 hosts
2023-04-30 20:32:06,239 -  nornir.core -     INFO -        run() - Running task 'netmiko_save_config' with args {} on 1 hosts
